{
  "artifacts": [],
  "command": "my_main",
  "experiment": {
    "base_dir": "/icnn/RL/src",
    "dependencies": [
      "dill==0.2.8.2",
      "gym==0.10.9",
      "munch==2.3.2",
      "numpy==1.16.0",
      "pymongo==3.7.2",
      "PyYAML==3.13",
      "sacred==0.7.4",
      "setproctitle==1.1.10",
      "tensorflow-gpu==1.12.0"
    ],
    "mainfile": "main.py",
    "name": "pymarl",
    "repositories": [],
    "sources": [
      [
        "agent.py",
        "_sources/agent_f6cc9e64a0c64a8093c662412487de8b.py"
      ],
      [
        "main.py",
        "_sources/main_a805de65db79fa2c78934d6fb92bc0bf.py"
      ],
      [
        "normalized_env.py",
        "_sources/normalized_env_3b239ca1da7769528b12449670494bad.py"
      ],
      [
        "runtime_env.py",
        "_sources/runtime_env_768922343370b7a4dc9f3c9aa7b5fde5.py"
      ],
      [
        "utils/__init__.py",
        "_sources/__init___d41d8cd98f00b204e9800998ecf8427e.py"
      ],
      [
        "utils/dict2namedtuple.py",
        "_sources/dict2namedtuple_0afb1ea09dbaa5798eb9185aeaa09a13.py"
      ],
      [
        "utils/logging.py",
        "_sources/logging_35a5d480ff8d4889ba1e8320767e94ab.py"
      ]
    ]
  },
  "fail_trace": [
    "Traceback (most recent call last):\n",
    "  File \"/usr/local/lib/python3.5/dist-packages/tensorflow/python/pywrap_tensorflow_internal.py\", line 1054, in __init__\n    self.this.append(this)\n",
    "  File \"/usr/local/lib/python3.5/dist-packages/tensorflow/python/pywrap_tensorflow_internal.py\", line 1040, in <lambda>\n    __getattr__ = lambda self, name: _swig_getattr(self, TF_Output, name)\n",
    "  File \"/usr/local/lib/python3.5/dist-packages/tensorflow/python/pywrap_tensorflow_internal.py\", line 74, in _swig_getattr\n    return _swig_getattr_nondynamic(self, class_type, name, 0)\n",
    "  File \"/usr/local/lib/python3.5/dist-packages/tensorflow/python/pywrap_tensorflow_internal.py\", line 69, in _swig_getattr_nondynamic\n    return object.__getattr__(self, name)\n",
    "AttributeError: type object 'object' has no attribute '__getattr__'\n",
    "\nDuring handling of the above exception, another exception occurred:\n\n",
    "Traceback (most recent call last):\n",
    "  File \"/usr/local/lib/python3.5/dist-packages/sacred/config/captured_function.py\", line 46, in captured_function\n    result = wrapped(*args, **kwargs)\n",
    "  File \"RL/src/main.py\", line 208, in my_main\n    runtime_env.run(mainer, FLAGS.outdir)\n",
    "  File \"/icnn/RL/src/runtime_env.py\", line 34, in run\n    Executor(main, outdir).execute()\n",
    "  File \"/icnn/RL/src/runtime_env.py\", line 82, in execute\n    self.main()\n",
    "  File \"RL/src/main.py\", line 205, in mainer\n    ExperimentICNN().run(logger)\n",
    "  File \"RL/src/main.py\", line 55, in run\n    test=True, monitor=np.random.rand() < FLAGS.monitor, ts=self.train_timestep, _logger=_logger)\n",
    "  File \"RL/src/main.py\", line 98, in run_episode\n    action = self.agent.act(test=test)\n",
    "  File \"/icnn/RL/src/naf.py\", line 118, in act\n    action = self._act_test(obs, False) if test else self._act_expl(obs, False)\n",
    "  File \"/icnn/RL/src/naf.py\", line 172, in __call__\n    res = self._session.run(out, feeds)\n",
    "  File \"/usr/local/lib/python3.5/dist-packages/tensorflow/python/client/session.py\", line 929, in run\n    run_metadata_ptr)\n",
    "  File \"/usr/local/lib/python3.5/dist-packages/tensorflow/python/client/session.py\", line 1152, in _run\n    feed_dict_tensor, options, run_metadata)\n",
    "  File \"/usr/local/lib/python3.5/dist-packages/tensorflow/python/client/session.py\", line 1310, in _do_run\n    feeds = dict((t._as_tf_output(), v) for t, v in feed_dict.items())\n",
    "  File \"/usr/local/lib/python3.5/dist-packages/tensorflow/python/client/session.py\", line 1310, in <genexpr>\n    feeds = dict((t._as_tf_output(), v) for t, v in feed_dict.items())\n",
    "  File \"/usr/local/lib/python3.5/dist-packages/tensorflow/python/framework/ops.py\", line 604, in _as_tf_output\n    return c_api_util.tf_output(self.op._c_op, self.value_index)\n",
    "  File \"/usr/local/lib/python3.5/dist-packages/tensorflow/python/framework/c_api_util.py\", line 184, in tf_output\n    ret = c_api.TF_Output()\n",
    "  File \"/usr/local/lib/python3.5/dist-packages/tensorflow/python/pywrap_tensorflow_internal.py\", line 1054, in __init__\n    self.this.append(this)\n",
    "  File \"/icnn/RL/src/runtime_env.py\", line 66, in on_kill\n    sys.exit(-1)\n",
    "SystemExit: -1\n"
  ],
  "heartbeat": "2019-01-25T16:30:06.120172",
  "host": {
    "ENV": {},
    "cpu": "Intel(R) Xeon(R) CPU E5-2697 v4 @ 2.30GHz",
    "gpus": {
      "driver_version": "390.77",
      "gpus": [
        {
          "model": "GeForce GTX 1080 Ti",
          "persistence_mode": false,
          "total_memory": 11178
        }
      ]
    },
    "hostname": "savitar",
    "os": [
      "Linux",
      "Linux-4.4.0-62-generic-x86_64-with-Ubuntu-16.04-xenial"
    ],
    "python_version": "3.5.2"
  },
  "meta": {
    "command": "my_main",
    "options": {
      "--beat_interval": null,
      "--capture": null,
      "--comment": null,
      "--debug": false,
      "--enforce_clean": false,
      "--file_storage": null,
      "--force": false,
      "--help": false,
      "--loglevel": null,
      "--mongo_db": null,
      "--name": null,
      "--pdb": false,
      "--print_config": false,
      "--priority": null,
      "--queue": false,
      "--sql": null,
      "--tiny_db": null,
      "--unobserved": false,
      "COMMAND": null,
      "UPDATE": [],
      "help": false,
      "with": false
    }
  },
  "resources": [],
  "result": null,
  "start_time": "2019-01-25T16:21:03.881852",
  "status": "FAILED",
  "stop_time": "2019-01-25T16:30:06.251273"
}